[2023-07-13T12:50:56.369+0000] {taskinstance.py:1103} INFO - Dependencies all met for dep_context=non-requeueable deps ti=<TaskInstance: thyroid_preprocessing_DAG.fit_xgboost manual__2023-07-13T12:48:55.842447+00:00 [queued]>
[2023-07-13T12:50:56.390+0000] {taskinstance.py:1103} INFO - Dependencies all met for dep_context=requeueable deps ti=<TaskInstance: thyroid_preprocessing_DAG.fit_xgboost manual__2023-07-13T12:48:55.842447+00:00 [queued]>
[2023-07-13T12:50:56.390+0000] {taskinstance.py:1308} INFO - Starting attempt 1 of 1
[2023-07-13T12:50:56.415+0000] {taskinstance.py:1327} INFO - Executing <Task(PythonOperator): fit_xgboost> on 2023-07-13 12:48:55.842447+00:00
[2023-07-13T12:50:56.426+0000] {standard_task_runner.py:57} INFO - Started process 1070 to run task
[2023-07-13T12:50:56.433+0000] {standard_task_runner.py:84} INFO - Running: ['***', 'tasks', 'run', 'thyroid_preprocessing_DAG', 'fit_xgboost', 'manual__2023-07-13T12:48:55.842447+00:00', '--job-id', '1000', '--raw', '--subdir', 'DAGS_FOLDER/dagfile.py', '--cfg-path', '/tmp/tmp0fdjzoep']
[2023-07-13T12:50:56.434+0000] {standard_task_runner.py:85} INFO - Job 1000: Subtask fit_xgboost
[2023-07-13T12:50:56.511+0000] {task_command.py:410} INFO - Running <TaskInstance: thyroid_preprocessing_DAG.fit_xgboost manual__2023-07-13T12:48:55.842447+00:00 [running]> on host 93aa310e5d41
[2023-07-13T12:50:56.650+0000] {taskinstance.py:1547} INFO - Exporting env vars: AIRFLOW_CTX_DAG_EMAIL='damirbogdan39@gmail.com' AIRFLOW_CTX_DAG_OWNER='aiflow' AIRFLOW_CTX_DAG_ID='thyroid_preprocessing_DAG' AIRFLOW_CTX_TASK_ID='fit_xgboost' AIRFLOW_CTX_EXECUTION_DATE='2023-07-13T12:48:55.842447+00:00' AIRFLOW_CTX_TRY_NUMBER='1' AIRFLOW_CTX_DAG_RUN_ID='manual__2023-07-13T12:48:55.842447+00:00'
[2023-07-13T12:50:56.707+0000] {taskinstance.py:1824} ERROR - Task failed with exception
Traceback (most recent call last):
  File "/home/airflow/.local/lib/python3.7/site-packages/sklearn/metrics/_scorer.py", line 404, in get_scorer
    scorer = SCORERS[scoring]
KeyError: 'macro_recall'

During handling of the above exception, another exception occurred:

Traceback (most recent call last):
  File "/home/airflow/.local/lib/python3.7/site-packages/airflow/operators/python.py", line 181, in execute
    return_value = self.execute_callable()
  File "/home/airflow/.local/lib/python3.7/site-packages/airflow/operators/python.py", line 198, in execute_callable
    return self.python_callable(*self.op_args, **self.op_kwargs)
  File "/opt/airflow/dags/src/model/fit_model.py", line 43, in fit_xgboost
    grid_search.fit(X_train, y_train)  # X_train and y_train are your training data
  File "/home/airflow/.local/lib/python3.7/site-packages/sklearn/model_selection/_search.py", line 793, in fit
    scorers = check_scoring(self.estimator, self.scoring)
  File "/home/airflow/.local/lib/python3.7/site-packages/sklearn/metrics/_scorer.py", line 453, in check_scoring
    return get_scorer(scoring)
  File "/home/airflow/.local/lib/python3.7/site-packages/sklearn/metrics/_scorer.py", line 409, in get_scorer
    "to get valid options." % scoring
ValueError: 'macro_recall' is not a valid scoring value. Use sorted(sklearn.metrics.SCORERS.keys()) to get valid options.
[2023-07-13T12:50:56.737+0000] {taskinstance.py:1350} INFO - Marking task as FAILED. dag_id=thyroid_preprocessing_DAG, task_id=fit_xgboost, execution_date=20230713T124855, start_date=20230713T125056, end_date=20230713T125056
[2023-07-13T12:50:56.761+0000] {standard_task_runner.py:109} ERROR - Failed to execute job 1000 for task fit_xgboost ('macro_recall' is not a valid scoring value. Use sorted(sklearn.metrics.SCORERS.keys()) to get valid options.; 1070)
[2023-07-13T12:50:56.808+0000] {local_task_job_runner.py:225} INFO - Task exited with return code 1
[2023-07-13T12:50:56.871+0000] {taskinstance.py:2653} INFO - 0 downstream tasks scheduled from follow-on schedule check
