[2023-07-10T14:49:00.492+0000] {taskinstance.py:1103} INFO - Dependencies all met for dep_context=non-requeueable deps ti=<TaskInstance: thyroid_preprocessing_DAG.y_train manual__2023-07-10T14:48:00.106099+00:00 [queued]>
[2023-07-10T14:49:00.580+0000] {taskinstance.py:1103} INFO - Dependencies all met for dep_context=requeueable deps ti=<TaskInstance: thyroid_preprocessing_DAG.y_train manual__2023-07-10T14:48:00.106099+00:00 [queued]>
[2023-07-10T14:49:00.580+0000] {taskinstance.py:1308} INFO - Starting attempt 1 of 1
[2023-07-10T14:49:00.729+0000] {taskinstance.py:1327} INFO - Executing <Task(PythonOperator): y_train> on 2023-07-10 14:48:00.106099+00:00
[2023-07-10T14:49:00.845+0000] {standard_task_runner.py:57} INFO - Started process 1009 to run task
[2023-07-10T14:49:00.872+0000] {standard_task_runner.py:84} INFO - Running: ['***', 'tasks', 'run', 'thyroid_preprocessing_DAG', 'y_train', 'manual__2023-07-10T14:48:00.106099+00:00', '--job-id', '295', '--raw', '--subdir', 'DAGS_FOLDER/preprocess_dagfile.py', '--cfg-path', '/tmp/tmptsz7bbpu']
[2023-07-10T14:49:00.873+0000] {standard_task_runner.py:85} INFO - Job 295: Subtask y_train
[2023-07-10T14:49:01.312+0000] {task_command.py:410} INFO - Running <TaskInstance: thyroid_preprocessing_DAG.y_train manual__2023-07-10T14:48:00.106099+00:00 [running]> on host 93aa310e5d41
[2023-07-10T14:49:02.112+0000] {taskinstance.py:1547} INFO - Exporting env vars: AIRFLOW_CTX_DAG_EMAIL='damirbogdan39@gmail.com' AIRFLOW_CTX_DAG_OWNER='aiflow' AIRFLOW_CTX_DAG_ID='thyroid_preprocessing_DAG' AIRFLOW_CTX_TASK_ID='y_train' AIRFLOW_CTX_EXECUTION_DATE='2023-07-10T14:48:00.106099+00:00' AIRFLOW_CTX_TRY_NUMBER='1' AIRFLOW_CTX_DAG_RUN_ID='manual__2023-07-10T14:48:00.106099+00:00'
[2023-07-10T14:49:02.220+0000] {taskinstance.py:1824} ERROR - Task failed with exception
Traceback (most recent call last):
  File "/home/airflow/.local/lib/python3.7/site-packages/airflow/operators/python.py", line 181, in execute
    return_value = self.execute_callable()
  File "/home/airflow/.local/lib/python3.7/site-packages/airflow/operators/python.py", line 198, in execute_callable
    return self.python_callable(*self.op_args, **self.op_kwargs)
  File "/opt/airflow/dags/src/preprocess/train_test_pull.py", line 25, in load_y_train
    os.makedirs(save_directory, exist_ok=True)
  File "/usr/local/lib/python3.7/os.py", line 213, in makedirs
    makedirs(head, exist_ok=exist_ok)
  File "/usr/local/lib/python3.7/os.py", line 223, in makedirs
    mkdir(name, mode)
PermissionError: [Errno 13] Permission denied: '/data'
[2023-07-10T14:49:02.271+0000] {taskinstance.py:1350} INFO - Marking task as FAILED. dag_id=thyroid_preprocessing_DAG, task_id=y_train, execution_date=20230710T144800, start_date=20230710T144900, end_date=20230710T144902
[2023-07-10T14:49:02.390+0000] {standard_task_runner.py:109} ERROR - Failed to execute job 295 for task y_train ([Errno 13] Permission denied: '/data'; 1009)
[2023-07-10T14:49:02.502+0000] {local_task_job_runner.py:225} INFO - Task exited with return code 1
[2023-07-10T14:49:02.575+0000] {taskinstance.py:2653} INFO - 0 downstream tasks scheduled from follow-on schedule check
