[2023-07-10T15:10:21.040+0000] {taskinstance.py:1103} INFO - Dependencies all met for dep_context=non-requeueable deps ti=<TaskInstance: thyroid_preprocessing_DAG.X_test manual__2023-07-10T15:09:22.083456+00:00 [queued]>
[2023-07-10T15:10:21.110+0000] {taskinstance.py:1103} INFO - Dependencies all met for dep_context=requeueable deps ti=<TaskInstance: thyroid_preprocessing_DAG.X_test manual__2023-07-10T15:09:22.083456+00:00 [queued]>
[2023-07-10T15:10:21.111+0000] {taskinstance.py:1308} INFO - Starting attempt 1 of 1
[2023-07-10T15:10:21.351+0000] {taskinstance.py:1327} INFO - Executing <Task(PythonOperator): X_test> on 2023-07-10 15:09:22.083456+00:00
[2023-07-10T15:10:21.427+0000] {standard_task_runner.py:57} INFO - Started process 2155 to run task
[2023-07-10T15:10:21.481+0000] {standard_task_runner.py:84} INFO - Running: ['***', 'tasks', 'run', 'thyroid_preprocessing_DAG', 'X_test', 'manual__2023-07-10T15:09:22.083456+00:00', '--job-id', '377', '--raw', '--subdir', 'DAGS_FOLDER/preprocess_dagfile.py', '--cfg-path', '/tmp/tmpyqd1ux8_']
[2023-07-10T15:10:21.486+0000] {standard_task_runner.py:85} INFO - Job 377: Subtask X_test
[2023-07-10T15:10:22.720+0000] {task_command.py:410} INFO - Running <TaskInstance: thyroid_preprocessing_DAG.X_test manual__2023-07-10T15:09:22.083456+00:00 [running]> on host 93aa310e5d41
[2023-07-10T15:10:25.717+0000] {taskinstance.py:1547} INFO - Exporting env vars: AIRFLOW_CTX_DAG_EMAIL='damirbogdan39@gmail.com' AIRFLOW_CTX_DAG_OWNER='aiflow' AIRFLOW_CTX_DAG_ID='thyroid_preprocessing_DAG' AIRFLOW_CTX_TASK_ID='X_test' AIRFLOW_CTX_EXECUTION_DATE='2023-07-10T15:09:22.083456+00:00' AIRFLOW_CTX_TRY_NUMBER='1' AIRFLOW_CTX_DAG_RUN_ID='manual__2023-07-10T15:09:22.083456+00:00'
[2023-07-10T15:11:14.975+0000] {job.py:216} ERROR - Job heartbeat got an exception
Traceback (most recent call last):
  File "/home/airflow/.local/lib/python3.7/site-packages/sqlalchemy/engine/base.py", line 3366, in _wrap_pool_connect
    return fn()
  File "/home/airflow/.local/lib/python3.7/site-packages/sqlalchemy/pool/base.py", line 327, in connect
    return _ConnectionFairy._checkout(self)
  File "/home/airflow/.local/lib/python3.7/site-packages/sqlalchemy/pool/base.py", line 894, in _checkout
    fairy = _ConnectionRecord.checkout(pool)
  File "/home/airflow/.local/lib/python3.7/site-packages/sqlalchemy/pool/base.py", line 493, in checkout
    rec = pool._do_get()
  File "/home/airflow/.local/lib/python3.7/site-packages/sqlalchemy/pool/impl.py", line 256, in _do_get
    return self._create_connection()
  File "/home/airflow/.local/lib/python3.7/site-packages/sqlalchemy/pool/base.py", line 273, in _create_connection
    return _ConnectionRecord(self)
  File "/home/airflow/.local/lib/python3.7/site-packages/sqlalchemy/pool/base.py", line 388, in __init__
    self.__connect()
  File "/home/airflow/.local/lib/python3.7/site-packages/sqlalchemy/pool/base.py", line 691, in __connect
    pool.logger.debug("Error on connect(): %s", e)
  File "/home/airflow/.local/lib/python3.7/site-packages/sqlalchemy/util/langhelpers.py", line 72, in __exit__
    with_traceback=exc_tb,
  File "/home/airflow/.local/lib/python3.7/site-packages/sqlalchemy/util/compat.py", line 211, in raise_
    raise exception
  File "/home/airflow/.local/lib/python3.7/site-packages/sqlalchemy/pool/base.py", line 686, in __connect
    self.dbapi_connection = connection = pool._invoke_creator(self)
  File "/home/airflow/.local/lib/python3.7/site-packages/sqlalchemy/engine/create.py", line 574, in connect
    return dialect.connect(*cargs, **cparams)
  File "/home/airflow/.local/lib/python3.7/site-packages/sqlalchemy/engine/default.py", line 598, in connect
    return self.dbapi.connect(*cargs, **cparams)
  File "/home/airflow/.local/lib/python3.7/site-packages/psycopg2/__init__.py", line 122, in connect
    conn = _connect(dsn, connection_factory=connection_factory, **kwasync)
psycopg2.OperationalError: could not translate host name "postgres" to address: Temporary failure in name resolution


The above exception was the direct cause of the following exception:

Traceback (most recent call last):
  File "/home/airflow/.local/lib/python3.7/site-packages/airflow/jobs/job.py", line 212, in heartbeat
    heartbeat_callback(session)
  File "/home/airflow/.local/lib/python3.7/site-packages/airflow/utils/session.py", line 73, in wrapper
    return func(*args, **kwargs)
  File "/home/airflow/.local/lib/python3.7/site-packages/airflow/jobs/local_task_job_runner.py", line 243, in heartbeat_callback
    self.task_instance.refresh_from_db()
  File "/home/airflow/.local/lib/python3.7/site-packages/airflow/utils/session.py", line 76, in wrapper
    return func(*args, session=session, **kwargs)
  File "/home/airflow/.local/lib/python3.7/site-packages/airflow/models/taskinstance.py", line 811, in refresh_from_db
    ti = qry.one_or_none()
  File "/home/airflow/.local/lib/python3.7/site-packages/sqlalchemy/orm/query.py", line 2850, in one_or_none
    return self._iter().one_or_none()
  File "/home/airflow/.local/lib/python3.7/site-packages/sqlalchemy/orm/query.py", line 2919, in _iter
    execution_options={"_sa_orm_load_options": self.load_options},
  File "/home/airflow/.local/lib/python3.7/site-packages/sqlalchemy/orm/session.py", line 1716, in execute
    conn = self._connection_for_bind(bind)
  File "/home/airflow/.local/lib/python3.7/site-packages/sqlalchemy/orm/session.py", line 1556, in _connection_for_bind
    engine, execution_options
  File "/home/airflow/.local/lib/python3.7/site-packages/sqlalchemy/orm/session.py", line 750, in _connection_for_bind
    conn = bind.connect()
  File "/home/airflow/.local/lib/python3.7/site-packages/sqlalchemy/engine/base.py", line 3320, in connect
    return self._connection_cls(self, close_with_result=close_with_result)
  File "/home/airflow/.local/lib/python3.7/site-packages/sqlalchemy/engine/base.py", line 96, in __init__
    else engine.raw_connection()
  File "/home/airflow/.local/lib/python3.7/site-packages/sqlalchemy/engine/base.py", line 3399, in raw_connection
    return self._wrap_pool_connect(self.pool.connect, _connection)
  File "/home/airflow/.local/lib/python3.7/site-packages/sqlalchemy/engine/base.py", line 3370, in _wrap_pool_connect
    e, dialect, self
  File "/home/airflow/.local/lib/python3.7/site-packages/sqlalchemy/engine/base.py", line 2204, in _handle_dbapi_exception_noconnection
    sqlalchemy_exception, with_traceback=exc_info[2], from_=e
  File "/home/airflow/.local/lib/python3.7/site-packages/sqlalchemy/util/compat.py", line 211, in raise_
    raise exception
  File "/home/airflow/.local/lib/python3.7/site-packages/sqlalchemy/engine/base.py", line 3366, in _wrap_pool_connect
    return fn()
  File "/home/airflow/.local/lib/python3.7/site-packages/sqlalchemy/pool/base.py", line 327, in connect
    return _ConnectionFairy._checkout(self)
  File "/home/airflow/.local/lib/python3.7/site-packages/sqlalchemy/pool/base.py", line 894, in _checkout
    fairy = _ConnectionRecord.checkout(pool)
  File "/home/airflow/.local/lib/python3.7/site-packages/sqlalchemy/pool/base.py", line 493, in checkout
    rec = pool._do_get()
  File "/home/airflow/.local/lib/python3.7/site-packages/sqlalchemy/pool/impl.py", line 256, in _do_get
    return self._create_connection()
  File "/home/airflow/.local/lib/python3.7/site-packages/sqlalchemy/pool/base.py", line 273, in _create_connection
    return _ConnectionRecord(self)
  File "/home/airflow/.local/lib/python3.7/site-packages/sqlalchemy/pool/base.py", line 388, in __init__
    self.__connect()
  File "/home/airflow/.local/lib/python3.7/site-packages/sqlalchemy/pool/base.py", line 691, in __connect
    pool.logger.debug("Error on connect(): %s", e)
  File "/home/airflow/.local/lib/python3.7/site-packages/sqlalchemy/util/langhelpers.py", line 72, in __exit__
    with_traceback=exc_tb,
  File "/home/airflow/.local/lib/python3.7/site-packages/sqlalchemy/util/compat.py", line 211, in raise_
    raise exception
  File "/home/airflow/.local/lib/python3.7/site-packages/sqlalchemy/pool/base.py", line 686, in __connect
    self.dbapi_connection = connection = pool._invoke_creator(self)
  File "/home/airflow/.local/lib/python3.7/site-packages/sqlalchemy/engine/create.py", line 574, in connect
    return dialect.connect(*cargs, **cparams)
  File "/home/airflow/.local/lib/python3.7/site-packages/sqlalchemy/engine/default.py", line 598, in connect
    return self.dbapi.connect(*cargs, **cparams)
  File "/home/airflow/.local/lib/python3.7/site-packages/psycopg2/__init__.py", line 122, in connect
    conn = _connect(dsn, connection_factory=connection_factory, **kwasync)
sqlalchemy.exc.OperationalError: (psycopg2.OperationalError) could not translate host name "postgres" to address: Temporary failure in name resolution

(Background on this error at: https://sqlalche.me/e/14/e3q8)
[2023-07-10T15:11:51.996+0000] {python.py:183} INFO - Done. Returned value was:        age   sex  on_thyroxine  ...  FTI_measured    FTI  referral_source
3445  52.0     M             0  ...             1  112.0            other
1792  48.0     M             0  ...             1  107.0            other
3246  39.0     M             0  ...             1  107.0            other
2859  54.0     F             0  ...             1   94.0            other
3320  43.0     M             0  ...             1   88.0              SVI
...    ...   ...           ...  ...           ...    ...              ...
2601  50.0     F             1  ...             1  114.0            other
3362  25.0  None             1  ...             1  121.0             STMW
2314  74.0     F             0  ...             1  120.0              SVI
785   44.0     M             0  ...             1  130.0              SVI
142   34.0     F             0  ...             1   98.0            other

[1132 rows x 27 columns]
[2023-07-10T15:11:54.102+0000] {taskinstance.py:1350} INFO - Marking task as SUCCESS. dag_id=thyroid_preprocessing_DAG, task_id=X_test, execution_date=20230710T150922, start_date=20230710T151021, end_date=20230710T151154
[2023-07-10T15:11:54.337+0000] {local_task_job_runner.py:225} INFO - Task exited with return code 0
[2023-07-10T15:11:54.498+0000] {taskinstance.py:2653} INFO - 0 downstream tasks scheduled from follow-on schedule check
